<robot name="DHAL" xmlns:xacro="http://www.ros.org/wiki/xacro">
    <material name="black">
        <color rgba="0.0 0.0 0.0 1.0"/>
    </material>
    <material name="blue">
        <color rgba="0.0 0.0 0.8 1.0"/>
    </material>
    <material name="green">
        <color rgba="0.0 0.8 0.0 1.0"/>
    </material>
    <material name="grey">
        <color rgba="0.2 0.2 0.2 1.0"/>
    </material>
    <material name="silver">
        <color rgba="0.913725490196 0.913725490196 0.847058823529 1.0"/>
    </material>
    <material name="orange">
        <color rgba="1.0 0.423529411765 0.0392156862745 1.0"/>
    </material>
    <material name="brown">
        <color rgba="0.870588235294 0.811764705882 0.764705882353 1.0"/>
    </material>
    <material name="red">
        <color rgba="0.8 0.0 0.0 1.0"/>
    </material>
    <material name="white">
        <color rgba="1.0 1.0 1.0 1.0"/>
    </material>

    <link name="Pelvis">
        <visual>
            <origin rpy="0 0 0" xyz="0 0 0"/>
            <geometry>
                <box size="0.12 0.26 0.1"/>
            </geometry>
            <material name="grey"/>
        </visual>
        <collision>
            <origin rpy="0 0 0" xyz="0 0 0"/>
            <geometry>
                <box size="0.12 0.26 0.1"/>
            </geometry>
        </collision>
        <inertial>
            <origin rpy="0 0 0" xyz="0 0 0"/>
            <mass value="7.0"/>
            <inertia ixx="1.0" ixy="0.0" ixz="0.0" iyy="1.0" iyz="0.0" izz="1.0"/>
        </inertial>
    </link>

    <joint name="L_hip_yaw_joint" type="revolute">
        <origin rpy="0 0 0" xyz="0.0 0.1 -0.05"/>
        <parent link="Pelvis"/>
        <child link="L_Hip"/>
        <axis xyz="0 0 1"/>
        <dynamics rotor_inertia="0.0724" damping="0" friction="0"/>
        <limit effort="360.0" lower="-0.785398" upper="1.57079632679" velocity="10.0"/>
    </joint>
    <link name="L_Hip">
        <visual>
            <origin rpy="0 1.57079632679 0" xyz="0 0 -0.08"/>
            <geometry>
                <cylinder radius="0.06" length="0.08"/>
            </geometry>
            <material name="white"/>
        </visual>
        <collision>
            <origin rpy="0 1.57079632679 0" xyz="0 0 -0.08"/>
            <geometry>
                <cylinder radius="0.06" length="0.08"/>
            </geometry>
        </collision>
        <inertial>
            <origin rpy="0 1.57079632679 0" xyz="0 0 -0.08"/>
            <mass value="2.0"/>
            <inertia ixx="1.0" ixy="0.0" ixz="0.0" iyy="1.0" iyz="0.0" izz="1.0"/>
        </inertial>
    </link>

    <joint name="L_hip_roll_joint" type="revolute">
        <origin rpy="0 0 0" xyz="0.04 0.0 -0.08"/>
        <parent link="L_Hip"/>
        <child link="L_Hip_Pitch"/>
        <axis xyz="1 0 0"/>
        <dynamics rotor_inertia="0.0724" damping="0" friction="0"/>
        <limit effort="360.0" lower="-0.349066" upper="0.785398" velocity="10.0"/>
    </joint>
    <link name="L_Hip_Pitch">
        <visual>
            <origin rpy="1.57079632679 0 0" xyz="0.1 0 0"/>
            <geometry>
                <cylinder radius="0.08" length="0.13"/>
            </geometry>
            <material name="white"/>
        </visual>
        <collision>
            <origin rpy="1.57079632679 0 0" xyz="0.1 0 0"/>
            <geometry>
                <cylinder radius="0.08" length="0.13"/>
            </geometry>
        </collision>
        <inertial>
            <origin rpy="1.57079632679 0 0" xyz="0.1 0 0"/>
            <mass value="2.5"/>
            <inertia ixx="1.0" ixy="0.0" ixz="0.0" iyy="1.0" iyz="0.0" izz="1.0"/>
        </inertial>
    </link>

    <joint name="L_hip_pitch_joint" type="revolute">
        <origin rpy="0 0 0" xyz="0.1 0.065 0"/>
        <parent link="L_Hip_Pitch"/>
        <child link="L_Thigh"/>
        <axis xyz="0 1 0"/>
        <dynamics rotor_inertia="0.3608" damping="0" friction="0"/>
        <limit effort="600.0" lower="-1.57079632679" upper="1.57079632679" velocity="10.0"/>
    </joint>
    <link name="L_Thigh">
        <visual>
            <origin rpy="0 0 0" xyz="0 0.03 -0.2"/>
            <geometry>
                <box size="0.12 0.06 0.32"/>
            </geometry>
            <material name="grey"/>
        </visual>
        <!-- <collision>
            <origin rpy="0 0 0" xyz="0 0.03 -0.2"/>
            <geometry>
                <box size="0.12 0.06 0.32"/>
            </geometry>
        </collision> -->
        <inertial>
            <origin rpy="0 0 0" xyz="0 0.03 -0.2"/>
            <mass value="6.5"/>
            <inertia ixx="1.0" ixy="0.0" ixz="0.0" iyy="1.0" iyz="0.0" izz="1.0"/>
        </inertial>
    </link>

    <joint name="L_knee_joint" type="revolute">
        <origin rpy="0 0 0" xyz="0 0.03 -0.4"/>
        <parent link="L_Thigh"/>
        <child link="L_Calf"/>
        <axis xyz="0 1 0"/>
        <dynamics rotor_inertia="0.3608" damping="0" friction="0"/>
        <limit effort="600.0" lower="0.0872665" upper="2.35619" velocity="10.0"/>
    </joint>
    <link name="L_Calf">
        <visual>
            <origin rpy="0 0 0" xyz="0 0 -0.205"/>
            <geometry>
                <box size="0.1 0.05 0.30"/>
            </geometry>
            <material name="grey"/>
        </visual>
        <collision>
            <origin rpy="0 0 0" xyz="0 0 -0.205"/>
            <geometry>
                <box size="0.1 0.05 0.30"/>
            </geometry>
        </collision>
        <inertial>
            <origin rpy="0 0 0" xyz="0 0 -0.205"/>
            <mass value="4.5"/>
            <inertia ixx="1.0" ixy="0.0" ixz="0.0" iyy="1.0" iyz="0.0" izz="1.0"/>
        </inertial>
    </link>

    <!-- closed loop left-->
    <joint name="L_Calf_Close_Upper_Left_Passive_Joint" type="revolute">
        <origin rpy="0 0 0" xyz="-0.05 0.05 -0.1"/>
        <parent link="L_Calf"/>
        <child link="L_Calf_Close_Left"/>
        <axis xyz="0 1 0"/>
        <dynamics rotor_inertia="0.0" damping="0" friction="0"/>
        <limit effort="150.0" lower="-0.75" upper="0.75" velocity="10.0"/>
    </joint>
    <link name="L_Calf_Close_Left">
        <visual>
            <origin rpy="0 0 0" xyz="0.02 -0.00 -0.0"/>
            <geometry>
                <box size="0.1 0.02 0.05"/>
            </geometry>
            <material name="grey"/>
        </visual>
        <collision>
            <origin rpy="0 0 0" xyz="0.02 0.0 -0.0"/>
            <geometry>
                <box size="0.01 0.01 0.01"/>
            </geometry>
        </collision>
        <inertial>
            <origin rpy="0 0 0" xyz="0.02 -0.0 -0.0"/>
            <mass value="0.5"/>
            <inertia ixx="1.0" ixy="0.0" ixz="0.0" iyy="1.0" iyz="0.0" izz="1.0"/>
        </inertial>
    </link>

    <joint name="L_Rod_Upper_Left_Passive_Joint" type="revolute">
        <origin rpy="0 0 0" xyz="-0.1 0 -0."/>
        <parent link="L_Calf_Close_Left"/>
        <child link="L_Rod_Close_Left"/>
        <axis xyz="0 1 0"/>
        <dynamics rotor_inertia="0.0" damping="0" friction="0"/>
        <limit effort="150.0" lower="-0.75" upper="0.75" velocity="10.0"/>
    </joint>
    <link name="L_Rod_Close_Left">
        <visual>
            <origin rpy="0 0 0" xyz="0 -0.0 -0.20"/>
            <geometry>
                <box size="0.01 0.01 0.30"/>
            </geometry>
            <material name="grey"/>
        </visual>
        <collision>
            <origin rpy="0 0 0" xyz="0 -0.0 -0.15"/>
            <geometry>
                <box size="0.01 0.01 0.30"/>
            </geometry>
        </collision>
        <inertial>
            <origin rpy="0 0 0" xyz="0 -0.0 -0.15"/>
            <mass value="0.5"/>
            <inertia ixx="1.0" ixy="0.0" ixz="0.0" iyy="1.0" iyz="0.0" izz="1.0"/>
        </inertial>
    </link>
    <joint name="L_Heel_Left_Joint" type="revolute">
        <origin rpy="0 0 0" xyz="-0. -0. -0.35"/>
        <parent link="L_Rod_Close_Left"/>
        <child link="L_Heel_Left"/>
        <axis xyz="1 0 0"/>
        <dynamics rotor_inertia="0.0" damping="0" friction="0"/>
        <limit effort="150.0" lower="-0.75" upper="0.75" velocity="10.0"/>
    </joint>

    <link name="L_Heel_Left">
        <visual>
            <origin rpy="0 0 0" xyz="0.03 0.02 -0.0"/>
            <geometry>
                <box size="0.05 0.05 0.05"/>
            </geometry>
            <material name="red"/>
        </visual>
        <collision>
            <origin rpy="0 0 0" xyz="0.03 -0.02 0.04"/>
            <geometry>
                <box size="0.01 0.01 0.02"/>
            </geometry>
        </collision>
        <inertial>
            <origin rpy="0 0 0" xyz="0.03 -0.02 0.04"/>
            <mass value="0.5"/>
            <inertia ixx="1.0" ixy="0.0" ixz="0.0" iyy="1.0" iyz="0.0" izz="1.0"/>
        </inertial>
    </link>

    <!-- closed loop right -->
    <joint name="L_Calf_Close_Upper_Right_Passive_Joint" type="revolute">
        <origin rpy="0 0 0" xyz="-0.05 -0.05 -0.1"/>
        <parent link="L_Calf"/>
        <child link="L_Calf_Close_Right"/>
        <axis xyz="0 1 0"/>
        <dynamics rotor_inertia="0.0" damping="0" friction="0"/>
        <limit effort="150.0" lower="-0.75" upper="0.75" velocity="10.0"/>
    </joint>
    <link name="L_Calf_Close_Right">
        <visual>
            <origin rpy="0 0 0" xyz="-0.02 -0.00 -0.0"/>
            <geometry>
                <box size="0.1 0.02 0.05"/>
            </geometry>
            <material name="grey"/>
        </visual>
        <collision>
            <origin rpy="0 0 0" xyz="-0.02 0.0 -0.0"/>
            <geometry>
                <box size="0.01 0.01 0.01"/>
            </geometry>
        </collision>
        <inertial>
            <origin rpy="0 0 0" xyz="-0.02 -0.0 -0.0"/>
            <mass value="0.5"/>
            <inertia ixx="1.0" ixy="0.0" ixz="0.0" iyy="1.0" iyz="0.0" izz="1.0"/>
        </inertial>
    </link>

    <joint name="L_Rod_Upper_Right_Passive_Joint" type="revolute">
        <origin rpy="0 0 0" xyz="-0.1 0 -0.0"/>
        <parent link="L_Calf_Close_Right"/>
        <child link="L_Rod_Close_Right"/>
        <axis xyz="0 1 0"/>
        <dynamics rotor_inertia="0.0" damping="0" friction="0"/>
        <limit effort="150.0" lower="-0.75" upper="0.75" velocity="10.0"/>
    </joint>
    <link name="L_Rod_Close_Right">
        <visual>
            <origin rpy="0 0 0" xyz="0 -0.0 -0.20"/>
            <geometry>
                <box size="0.01 0.01 0.30"/>
            </geometry>
            <material name="grey"/>
        </visual>
        <collision>
            <origin rpy="0 0 0" xyz="0 -0.0 -0.15"/>
            <geometry>
                <box size="0.01 0.01 0.30"/>
            </geometry>
        </collision>
        <inertial>
            <origin rpy="0 0 0" xyz="0 -0.0 -0.15"/>
            <mass value="0.5"/>
            <inertia ixx="1.0" ixy="0.0" ixz="0.0" iyy="1.0" iyz="0.0" izz="1.0"/>
        </inertial>
    </link>

    <joint name="L_Heel_Right_Joint" type="revolute">
        <origin rpy="0 0 0" xyz="-0. -0. -0.35"/>
        <parent link="L_Rod_Close_Right"/>
        <child link="L_Heel_Right"/>
        <axis xyz="1 0 0"/>
        <dynamics rotor_inertia="0.0" damping="0" friction="0"/>
        <limit effort="150.0" lower="-0.75" upper="0.75" velocity="10.0"/>
    </joint>

    <link name="L_Heel_Right">
        <visual>
            <origin rpy="0 0 0" xyz="0.03 -0.02 -0.0"/>
            <geometry>
                <box size="0.05 0.05 0.05"/>
            </geometry>
            <material name="red"/>
        </visual>
        <collision>
            <origin rpy="0 0 0" xyz="0.03 -0.02 0.04"/>
            <geometry>
                <box size="0.01 0.01 0.02"/>
            </geometry>
        </collision>
        <inertial>
            <origin rpy="0 0 0" xyz="0.03 -0.02 0.04"/>
            <mass value="0.5"/>
            <inertia ixx="1.0" ixy="0.0" ixz="0.0" iyy="1.0" iyz="0.0" izz="1.0"/>
        </inertial>
    </link>


    <!-- close loop end -->

    <joint name="L_ankle_pitch_joint" type="revolute">
        <origin rpy="0 0 0" xyz="0 0 -0.41"/>
        <parent link="L_Calf"/>
        <child link="L_Ankle"/>
        <axis xyz="0 1 0"/>
        <dynamics rotor_inertia="0.023168" damping="0" friction="0"/>
        <limit effort="150.0" lower="-1.22173" upper="0.349066" velocity="10.0"/>
    </joint>
    <link name="L_Ankle">
        <visual>
            <origin rpy="1.57079632679 0 0" xyz="0 0 0"/>
            <geometry>
                <cylinder length="0.05" radius="0.02"/>
            </geometry>
            <material name="white"/>
        </visual>
        <collision>
            <origin rpy="1.57079632679 0 0" xyz="0 0 0"/>
            <geometry>
                <cylinder length="0.06" radius="0.02"/>
            </geometry>
        </collision>
        <inertial>
            <origin rpy="1.57079632679 0 0" xyz="0 0 0"/>
            <mass value="0.01"/>
            <inertia ixx="1.0" ixy="0.0" ixz="0.0" iyy="1.0" iyz="0.0" izz="1.0"/>
        </inertial>
    </link>

    <joint name="L_ankle_roll_joint" type="revolute">
        <origin rpy="0 0 0" xyz="0 0 0"/>
        <parent link="L_Ankle"/>
        <child link="L_Foot"/>
        <axis xyz="1 0 0"/>
        <dynamics rotor_inertia="0.023168" damping="0" friction="0"/>
        <limit effort="150.0" lower="-0.523599" upper="0.523599" velocity="10.0"/>
    </joint>
    <link name="L_Foot">
        <visual>
            <origin rpy="0 0 0" xyz="0 0 -0.05"/>
            <geometry>
                <box size="0.2 0.06 0.02"/>
            </geometry>
            <material name="blue"/>
        </visual>
        <collision>
            <origin rpy="0 0 0" xyz="0 0 -0.05"/>
            <geometry>
                <box size="0.2 0.06 0.02"/>
            </geometry>
        </collision>
        <inertial>
            <origin rpy="0 0 0" xyz="0 0 -0.05"/>
            <mass value="0.5"/>
            <inertia ixx="1.0" ixy="0.0" ixz="0.0" iyy="1.0" iyz="0.0" izz="1.0"/>
        </inertial>
    </link>
    <joint name="L_Heel_Joint" type="fixed">
        <origin rpy="0 0 0" xyz="-0.05 0 -0.05"/>
        <parent link="L_Foot"/>
        <child link="L_Heel"/>
        <axis xyz="1 0 0"/>
        <dynamics rotor_inertia="0.023168" damping="0" friction="0"/>
        <limit effort="150.0" lower="-0.523599" upper="0.523599" velocity="10.0"/>
    </joint>

    <link name="L_Heel">
        <visual>
            <origin rpy="0 0 0" xyz="0 0 0.05"/>
            <geometry>
                <box size="0.05 0.05 0.05"/>
            </geometry>
            <material name="orange"/>
        </visual>
        <inertial>
            <origin rpy="0 0 0" xyz="0 0 0.05"/>
            <mass value="0.5"/>
            <inertia ixx="1.0" ixy="0.0" ixz="0.0" iyy="1.0" iyz="0.0" izz="1.0"/>
        </inertial>
    </link>
    <!-- =================================================== -->

    <joint name="R_hip_yaw_joint" type="revolute">
        <origin rpy="0 0 0" xyz="0.0 -0.1 -0.05"/>
        <parent link="Pelvis"/>
        <child link="R_Hip"/>
        <axis xyz="0 0 1"/>
        <dynamics rotor_inertia="0.0724" damping="0" friction="0"/>
        <limit effort="360.0" lower="-1.57079632679" upper="0.785398" velocity="10.0"/>
    </joint>
    <link name="R_Hip">
        <visual>
            <origin rpy="0 1.57079632679 0" xyz="0 0 -0.08"/>
            <geometry>
                <cylinder radius="0.06" length="0.08"/>
            </geometry>
            <material name="white"/>
        </visual>
        <collision>
            <origin rpy="0 1.57079632679 0" xyz="0 0 -0.08"/>
            <geometry>
                <cylinder radius="0.06" length="0.08"/>
            </geometry>
        </collision>
        <inertial>
            <origin rpy="0 1.57079632679 0" xyz="0 0 -0.08"/>
            <mass value="2.0"/>
            <inertia ixx="1.0" ixy="0.0" ixz="0.0" iyy="1.0" iyz="0.0" izz="1.0"/>
        </inertial>
    </link>

    <joint name="R_hip_roll_joint" type="revolute">
        <origin rpy="0 0 0" xyz="0.04 0.0 -0.08"/>
        <parent link="R_Hip"/>
        <child link="R_Hip_Pitch"/>
        <axis xyz="1 0 0"/>
        <dynamics rotor_inertia="0.0724" damping="0" friction="0"/>
        <limit effort="360.0" lower="-0.785398" upper="0.349066" velocity="10.0"/>
    </joint>
    <link name="R_Hip_Pitch">
        <visual>
            <origin rpy="1.57079632679 0 0" xyz="0.1 0 0"/>
            <geometry>
                <cylinder radius="0.08" length="0.13"/>
            </geometry>
            <material name="white"/>
        </visual>
        <collision>
            <origin rpy="1.57079632679 0 0" xyz="0.1 0 0"/>
            <geometry>
                <cylinder radius="0.08" length="0.13"/>
            </geometry>
        </collision>
        <inertial>
            <origin rpy="1.57079632679 0 0" xyz="0.1 0 0"/>
            <mass value="2.5"/>
            <inertia ixx="1.0" ixy="0.0" ixz="0.0" iyy="1.0" iyz="0.0" izz="1.0"/>
        </inertial>
    </link>

    <joint name="R_hip_pitch_joint" type="revolute">
        <origin rpy="0 0 0" xyz="0.1 -0.065 0"/>
        <parent link="R_Hip_Pitch"/>
        <child link="R_Thigh"/>
        <axis xyz="0 1 0"/>
        <dynamics rotor_inertia="0.3608" damping="0" friction="0"/>
        <limit effort="600.0" lower="-1.57079632679" upper="1.57079632679" velocity="10.0"/>
    </joint>
    <link name="R_Thigh">
        <visual>
            <origin rpy="0 0 0" xyz="0 -0.03 -0.2"/>
            <geometry>
                <box size="0.12 0.06 0.32"/>
            </geometry>
            <material name="grey"/>
        </visual>
        <!-- <collision>
            <origin rpy="0 0 0" xyz="0 -0.03 -0.2"/>
            <geometry>
                <box size="0.12 0.06 0.32"/>
            </geometry>
        </collision> -->
        <inertial>
            <origin rpy="0 0 0" xyz="0 -0.03 -0.2"/>
            <mass value="6.5"/>
            <inertia ixx="1.0" ixy="0.0" ixz="0.0" iyy="1.0" iyz="0.0" izz="1.0"/>
        </inertial>
    </link>

    <joint name="R_knee_joint" type="revolute">
        <origin rpy="0 0 0" xyz="0 -0.03 -0.4"/>
        <parent link="R_Thigh"/>
        <child link="R_Calf"/>
        <axis xyz="0 1 0"/>
        <dynamics rotor_inertia="0.3608" damping="0" friction="0"/>
        <limit effort="600.0" lower="0.0872665" upper="2.35619" velocity="10.0"/>
    </joint>
    <link name="R_Calf">
        <visual>
            <origin rpy="0 0 0" xyz="0 0 -0.205"/>
            <geometry>
                <box size="0.1 0.05 0.30"/>
            </geometry>
            <material name="grey"/>
        </visual>
        <collision>
            <origin rpy="0 0 0" xyz="0 0 -0.205"/>
            <geometry>
                <box size="0.1 0.05 0.30"/>
            </geometry>
        </collision>
        <inertial>
            <origin rpy="0 0 0" xyz="0 0 -0.205"/>
            <mass value="4.5"/>
            <inertia ixx="1.0" ixy="0.0" ixz="0.0" iyy="1.0" iyz="0.0" izz="1.0"/>
        </inertial>
    </link>

    <!-- closed loop left-->
    <joint name="R_Calf_Close_Upper_Left_Passive_Joint" type="revolute">
        <origin rpy="0 0 0" xyz="-0.05 0.05 -0.1"/>
        <parent link="R_Calf"/>
        <child link="R_Calf_Close_Left"/>
        <axis xyz="0 1 0"/>
        <dynamics rotor_inertia="0.0" damping="0" friction="0"/>
        <limit effort="150.0" lower="-0.75" upper="0.75" velocity="10.0"/>
    </joint>
    <link name="R_Calf_Close_Left">
        <visual>
            <origin rpy="0 0 0" xyz="0.02 -0.00 -0.0"/>
            <geometry>
                <box size="0.1 0.02 0.05"/>
            </geometry>
            <material name="grey"/>
        </visual>
        <collision>
            <origin rpy="0 0 0" xyz="0.02 0.0 -0.0"/>
            <geometry>
                <box size="0.01 0.01 0.01"/>
            </geometry>
        </collision>
        <inertial>
            <origin rpy="0 0 0" xyz="0.02 -0.0 -0.0"/>
            <mass value="0.5"/>
            <inertia ixx="1.0" ixy="0.0" ixz="0.0" iyy="1.0" iyz="0.0" izz="1.0"/>
        </inertial>
    </link>

    <joint name="R_Rod_Upper_Left_Passive_Joint" type="revolute">
        <origin rpy="0 0 0" xyz="-0.1 0 -0."/>
        <parent link="R_Calf_Close_Left"/>
        <child link="R_Rod_Close_Left"/>
        <axis xyz="0 1 0"/>
        <dynamics rotor_inertia="0.0" damping="0" friction="0"/>
        <limit effort="150.0" lower="-0.75" upper="0.75" velocity="10.0"/>
    </joint>
    <link name="R_Rod_Close_Left">
        <visual>
            <origin rpy="0 0 0" xyz="0 -0.0 -0.20"/>
            <geometry>
                <box size="0.01 0.01 0.30"/>
            </geometry>
            <material name="grey"/>
        </visual>
        <collision>
            <origin rpy="0 0 0" xyz="0 -0.0 -0.15"/>
            <geometry>
                <box size="0.01 0.01 0.30"/>
            </geometry>
        </collision>
        <inertial>
            <origin rpy="0 0 0" xyz="0 -0.0 -0.15"/>
            <mass value="0.5"/>
            <inertia ixx="1.0" ixy="0.0" ixz="0.0" iyy="1.0" iyz="0.0" izz="1.0"/>
        </inertial>
    </link>
    <joint name="R_Heel_Left_Joint" type="revolute">
        <origin rpy="0 0 0" xyz="-0. -0. -0.35"/>
        <parent link="R_Rod_Close_Left"/>
        <child link="R_Heel_Left"/>
        <axis xyz="1 0 0"/>
        <dynamics rotor_inertia="0.0" damping="0" friction="0"/>
        <limit effort="150.0" lower="-0.75" upper="0.75" velocity="10.0"/>
    </joint>

    <link name="R_Heel_Left">
        <visual>
            <origin rpy="0 0 0" xyz="0.03 0.02 -0.0"/>
            <geometry>
                <box size="0.05 0.05 0.05"/>
            </geometry>
            <material name="red"/>
        </visual>
        <collision>
            <origin rpy="0 0 0" xyz="0.03 -0.02 0.04"/>
            <geometry>
                <box size="0.01 0.01 0.02"/>
            </geometry>
        </collision>
        <inertial>
            <origin rpy="0 0 0" xyz="0.03 -0.02 0.04"/>
            <mass value="0.5"/>
            <inertia ixx="1.0" ixy="0.0" ixz="0.0" iyy="1.0" iyz="0.0" izz="1.0"/>
        </inertial>
    </link>
    <!-- closed loop right -->
    <joint name="R_Calf_Close_Upper_Right_Passive_Joint" type="revolute">
        <origin rpy="0 0 0" xyz="-0.05 -0.05 -0.1"/>
        <parent link="R_Calf"/>
        <child link="R_Calf_Close_Right"/>
        <axis xyz="0 1 0"/>
        <dynamics rotor_inertia="0.0" damping="0" friction="0"/>
        <limit effort="150.0" lower="-0.75" upper="0.75" velocity="10.0"/>
    </joint>
    <link name="R_Calf_Close_Right">
        <visual>
            <origin rpy="0 0 0" xyz="0.02 -0.00 -0.0"/>
            <geometry>
                <box size="0.1 0.02 0.05"/>
            </geometry>
            <material name="grey"/>
        </visual>
        <collision>
            <origin rpy="0 0 0" xyz="0.02 0.0 -0.0"/>
            <geometry>
                <box size="0.01 0.01 0.01"/>
            </geometry>
        </collision>
        <inertial>
            <origin rpy="0 0 0" xyz="0.02 -0.0 -0.0"/>
            <mass value="0.5"/>
            <inertia ixx="1.0" ixy="0.0" ixz="0.0" iyy="1.0" iyz="0.0" izz="1.0"/>
        </inertial>
    </link>

    <joint name="R_Rod_Upper_Right_Passive_Joint" type="revolute">
        <origin rpy="0 0 0" xyz="-0.1 0 -0.0"/>
        <parent link="R_Calf_Close_Right"/>
        <child link="R_Rod_Close_Right"/>
        <axis xyz="0 1 0"/>
        <dynamics rotor_inertia="0.0" damping="0" friction="0"/>
        <limit effort="150.0" lower="-0.75" upper="0.75" velocity="10.0"/>
    </joint>
    <link name="R_Rod_Close_Right">
        <visual>
            <origin rpy="0 0 0" xyz="0 -0.0 -0.20"/>
            <geometry>
                <box size="0.01 0.01 0.30"/>
            </geometry>
            <material name="grey"/>
        </visual>
        <collision>
            <origin rpy="0 0 0" xyz="0 -0.0 -0.15"/>
            <geometry>
                <box size="0.01 0.01 0.30"/>
            </geometry>
        </collision>
        <inertial>
            <origin rpy="0 0 0" xyz="0 -0.0 -0.15"/>
            <mass value="0.5"/>
            <inertia ixx="1.0" ixy="0.0" ixz="0.0" iyy="1.0" iyz="0.0" izz="1.0"/>
        </inertial>
    </link>
    <joint name="R_Heel_Right_Joint" type="revolute">
        <origin rpy="0 0 0" xyz="-0. -0. -0.35"/>
        <parent link="R_Rod_Close_Right"/>
        <child link="R_Heel_Right"/>
        <axis xyz="1 0 0"/>
        <dynamics rotor_inertia="0.0" damping="0" friction="0"/>
        <limit effort="150.0" lower="-0.75" upper="0.75" velocity="10.0"/>
    </joint>

    <link name="R_Heel_Right">
        <visual>
            <origin rpy="0 0 0" xyz="0.03 -0.02 -0.0"/>
            <geometry>
                <box size="0.05 0.05 0.05"/>
            </geometry>
            <material name="red"/>
        </visual>
        <collision>
            <origin rpy="0 0 0" xyz="0.03 -0.02 0.04"/>
            <geometry>
                <box size="0.01 0.01 0.02"/>
            </geometry>
        </collision>
        <inertial>
            <origin rpy="0 0 0" xyz="0.03 -0.02 0.04"/>
            <mass value="0.5"/>
            <inertia ixx="1.0" ixy="0.0" ixz="0.0" iyy="1.0" iyz="0.0" izz="1.0"/>
        </inertial>
    </link>


    <!-- close loop end -->

    <joint name="R_ankle_pitch_joint" type="revolute">
        <origin rpy="0 0 0" xyz="0 0 -0.41"/>
        <parent link="R_Calf"/>
        <child link="R_Ankle"/>
        <axis xyz="0 1 0"/>
        <dynamics rotor_inertia="0.023168" damping="0" friction="0"/>
        <limit effort="150.0" lower="-1.22173" upper="0.349066" velocity="10.0"/>
    </joint>
    <link name="R_Ankle">
        <visual>
            <origin rpy="1.57079632679 0 0" xyz="0 0 0"/>
            <geometry>
                <cylinder length="0.05" radius="0.02"/>
            </geometry>
            <material name="white"/>
        </visual>
        <collision>
            <origin rpy="1.57079632679 0 0" xyz="0 0 0"/>
            <geometry>
                <cylinder length="0.06" radius="0.02"/>
            </geometry>
        </collision>
        <inertial>
            <origin rpy="1.57079632679 0 0" xyz="0 0 0"/>
            <mass value="0.01"/>
            <inertia ixx="1.0" ixy="0.0" ixz="0.0" iyy="1.0" iyz="0.0" izz="1.0"/>
        </inertial>
    </link>

    <joint name="R_ankle_roll_joint" type="revolute">
        <origin rpy="0 0 0" xyz="0 0 0"/>
        <parent link="R_Ankle"/>
        <child link="R_Foot"/>
        <axis xyz="1 0 0"/>
        <dynamics rotor_inertia="0.023168" damping="0" friction="0"/>
        <limit effort="150.0" lower="-0.523599" upper="0.523599" velocity="10.0"/>
    </joint>
    <link name="R_Foot">
        <visual>
            <origin rpy="0 0 0" xyz="0 0 -0.05"/>
            <geometry>
                <box size="0.2 0.06 0.02"/>
            </geometry>
            <material name="red"/>
        </visual>
        <collision>
            <origin rpy="0 0 0" xyz="0 0 -0.05"/>
            <geometry>
                <box size="0.2 0.06 0.02"/>
            </geometry>
        </collision>
        <inertial>
            <origin rpy="0 0 0" xyz="0 0 -0.05"/>
            <mass value="0.5"/>
            <inertia ixx="1.0" ixy="0.0" ixz="0.0" iyy="1.0" iyz="0.0" izz="1.0"/>
        </inertial>
    </link>

    <joint name="R_Heel_Joint" type="fixed">
        <origin rpy="0 0 0" xyz="-0.05 0 -0.05"/>
        <parent link="R_Foot"/>
        <child link="R_Heel"/>
        <axis xyz="1 0 0"/>
        <dynamics rotor_inertia="0.023168" damping="0" friction="0"/>
        <limit effort="150.0" lower="-0.523599" upper="0.523599" velocity="10.0"/>
    </joint>

    <link name="R_Heel">
        <visual>
            <origin rpy="0 0 0" xyz="0 0 0.05"/>
            <geometry>
                <box size="0.05 0.05 0.05"/>
            </geometry>
            <material name="orange"/>
        </visual>
        <inertial>
            <origin rpy="0 0 0" xyz="0 0 0.05"/>
            <mass value="0.5"/>
            <inertia ixx="1.0" ixy="0.0" ixz="0.0" iyy="1.0" iyz="0.0" izz="1.0"/>
        </inertial>
    </link>


    <joint name="waist_yaw_joint" type="revolute">
        <origin rpy="0 0 0" xyz="0 0 0.05"/>
        <parent link="Pelvis"/>
        <child link="Torso"/>
        <axis xyz="0 0 1"/>
        <dynamics rotor_inertia="0.0724" damping="0" friction="0"/>
        <limit effort="360.0" lower="-0.785398" upper="0.785398" velocity="10.0"/>
    </joint>
    <link name="Torso">
        <visual>
            <origin rpy="0 0 0" xyz="0 0 0.22"/>
            <geometry>
                <box size="0.14 0.3 0.4"/>
            </geometry>
            <material name="grey"/>
        </visual>
        <collision>
            <origin rpy="0 0 0" xyz="0 0 0.22"/>
            <geometry>
                <box size="0.14 0.3 0.4"/>
            </geometry>
        </collision>
        <inertial>
            <origin rpy="0 0 0" xyz="0 0 0.22"/>
            <mass value="12"/>
            <inertia ixx="1.0" ixy="0.0" ixz="0.0" iyy="1.0" iyz="0.0" izz="1.0"/>
        </inertial>
    </link>

    <constraints nominal_config="0 0 1.0 1.0 0 0 0 0 0 -0.174533 0.523599 0.0 0.0 0 0 0 0 -0.349066 0 0 0 -0.174533 0.523599 0.0 0.0 0 0 0 0 -0.349066 0.0">
        <pin body1="R_Heel" body2="R_Heel_Right" anchor="-0.0 -0.04 0.0"/>
        <pin body1="R_Heel" body2="R_Heel_Left" anchor="0.0 0.04 0.0"/>
        <pin body1="L_Heel" body2="L_Heel_Right" anchor="-0.0 -0.04 0.0"/>
        <pin body1="L_Heel" body2="L_Heel_Left" anchor="0.0 0.04 0.0"/>
<!--        <pin body1="R_Calf_Close_Left" body2="R_Rod_Close_Left" anchor="-0.1 0.0 0.0"/>-->
<!--        <pin body1="R_Calf_Close_Right" body2="R_Rod_Close_Right" anchor="-0.1 0.0 0.0"/>-->
<!--        <pin body1="L_Calf_Close_Left" body2="L_Rod_Close_Left" anchor="-0.1 0.0 0.0"/>-->
<!--        <pin body1="L_Calf_Close_Right" body2="L_Rod_Close_Right" anchor="-0.1 0.0 0.0"/>-->
    </constraints>
</robot>
